{
 "cells": [
  {
   "cell_type": "code",
   "execution_count": 4,
   "id": "7200ee98",
   "metadata": {},
   "outputs": [],
   "source": [
    "from PIL import Image\n",
    "import os\n",
    "from keras.utils import to_categorical\n",
    "from keras.models import Sequential\n",
    "from keras.layers import Conv2D, MaxPooling2D, Flatten, Dense, Dropout\n",
    "from keras.optimizers import Adam\n",
    "from keras.preprocessing.image import ImageDataGenerator"
   ]
  },
  {
   "cell_type": "code",
   "execution_count": 5,
   "id": "e7710b47",
   "metadata": {},
   "outputs": [],
   "source": [
    "# set results_folder to the folder in the same directory with the name \"results\"\n",
    "results_folder = '../results/'\n",
    "# Loop through every folder in results_folder. For each image inside the folder, add a label to the list of labels.\n",
    "labels = []\n",
    "for folder in os.listdir(results_folder):\n",
    "    for image in os.listdir(results_folder + folder):\n",
    "        labels.append(folder)\n",
    "# Create a list of all the images in the results_folder\n",
    "images = [os.path.join(results_folder, folder, image) for folder in os.listdir(results_folder) for image in os.listdir(results_folder + folder)]"
   ]
  },
  {
   "cell_type": "code",
   "execution_count": 6,
   "id": "0b82015f",
   "metadata": {},
   "outputs": [],
   "source": [
    "# Use one hot encoding\n",
    "matrix = {}\n",
    "length = len(labels)\n",
    "for i in range(length):\n",
    "    matrix[images[i]] = to_categorical(labels.index(labels[i]), num_classes=length"
   ]
  },
  {
   "cell_type": "code",
   "execution_count": null,
   "id": "48d9ab30",
   "metadata": {},
   "outputs": [],
   "source": [
    "# Create the model\n",
    "model = Sequential()\n",
    "model.add(Conv2D(32, (3, 3), input_shape=(32, 32, 3), activation='relu'))\n",
    "# Flatten\n",
    "model.add(Flatten())\n",
    "# Dense\n",
    "model.add(Dense(128, activation='relu'))\n",
    "# Output layer\n",
    "model.add(Dense(10, activation='softmax'))"
   ]
  },
  {
   "cell_type": "code",
   "execution_count": null,
   "id": "e6c7e6ae",
   "metadata": {},
   "outputs": [
    {
     "name": "stdout",
     "output_type": "stream",
     "text": [
      "Found 273728 images belonging to 64 classes.\n",
      "Found 273728 images belonging to 64 classes.\n"
     ]
    }
   ],
   "source": [
    "model.compile(loss='categorical_crossentropy', optimizer=Adam(), metrics=['accuracy'])\n",
    "# Create a generator that will take the data and create batches of size 32\n",
    "train_datagen = ImageDataGenerator(shear_range=0.2, zoom_range=0.2, horizontal_flip=True)\n",
    "test_datagen = ImageDataGenerator()\n",
    "train_generator = train_datagen.flow_from_directory(results_folder, target_size=(200, 200), batch_size=42, class_mode='categorical')\n",
    "test_generator = test_datagen.flow_from_directory(results_folder, target_size=(200, 200), batch_size=42, class_mode='categorical')"
   ]
  },
  {
   "cell_type": "code",
   "execution_count": null,
   "id": "0d682ebe",
   "metadata": {},
   "outputs": [
    {
     "name": "stderr",
     "output_type": "stream",
     "text": [
      "C:\\Users\\gurba\\AppData\\Local\\Temp\\ipykernel_12728\\2186535113.py:2: UserWarning: `Model.fit_generator` is deprecated and will be removed in a future version. Please use `Model.fit`, which supports generators.\n",
      "  model.fit_generator(train_generator, steps_per_epoch=42, epochs=10, validation_data=test_generator, validation_steps=42)\n"
     ]
    },
    {
     "name": "stdout",
     "output_type": "stream",
     "text": [
      "Epoch 1/10\n"
     ]
    },
    {
     "ename": "InvalidArgumentError",
     "evalue": "Graph execution error:\n\nDetected at node 'sequential_2/flatten_2/Reshape' defined at (most recent call last):\n    File \"c:\\Users\\gurba\\AppData\\Local\\Programs\\Python\\Python38\\lib\\runpy.py\", line 194, in _run_module_as_main\n      return _run_code(code, main_globals, None,\n    File \"c:\\Users\\gurba\\AppData\\Local\\Programs\\Python\\Python38\\lib\\runpy.py\", line 87, in _run_code\n      exec(code, run_globals)\n    File \"c:\\Users\\gurba\\AppData\\Local\\Programs\\Python\\Python38\\lib\\site-packages\\ipykernel_launcher.py\", line 17, in <module>\n      app.launch_new_instance()\n    File \"c:\\Users\\gurba\\AppData\\Local\\Programs\\Python\\Python38\\lib\\site-packages\\traitlets\\config\\application.py\", line 976, in launch_instance\n      app.start()\n    File \"c:\\Users\\gurba\\AppData\\Local\\Programs\\Python\\Python38\\lib\\site-packages\\ipykernel\\kernelapp.py\", line 712, in start\n      self.io_loop.start()\n    File \"c:\\Users\\gurba\\AppData\\Local\\Programs\\Python\\Python38\\lib\\site-packages\\tornado\\platform\\asyncio.py\", line 215, in start\n      self.asyncio_loop.run_forever()\n    File \"c:\\Users\\gurba\\AppData\\Local\\Programs\\Python\\Python38\\lib\\asyncio\\base_events.py\", line 570, in run_forever\n      self._run_once()\n    File \"c:\\Users\\gurba\\AppData\\Local\\Programs\\Python\\Python38\\lib\\asyncio\\base_events.py\", line 1859, in _run_once\n      handle._run()\n    File \"c:\\Users\\gurba\\AppData\\Local\\Programs\\Python\\Python38\\lib\\asyncio\\events.py\", line 81, in _run\n      self._context.run(self._callback, *self._args)\n    File \"c:\\Users\\gurba\\AppData\\Local\\Programs\\Python\\Python38\\lib\\site-packages\\ipykernel\\kernelbase.py\", line 510, in dispatch_queue\n      await self.process_one()\n    File \"c:\\Users\\gurba\\AppData\\Local\\Programs\\Python\\Python38\\lib\\site-packages\\ipykernel\\kernelbase.py\", line 499, in process_one\n      await dispatch(*args)\n    File \"c:\\Users\\gurba\\AppData\\Local\\Programs\\Python\\Python38\\lib\\site-packages\\ipykernel\\kernelbase.py\", line 406, in dispatch_shell\n      await result\n    File \"c:\\Users\\gurba\\AppData\\Local\\Programs\\Python\\Python38\\lib\\site-packages\\ipykernel\\kernelbase.py\", line 730, in execute_request\n      reply_content = await reply_content\n    File \"c:\\Users\\gurba\\AppData\\Local\\Programs\\Python\\Python38\\lib\\site-packages\\ipykernel\\ipkernel.py\", line 383, in do_execute\n      res = shell.run_cell(\n    File \"c:\\Users\\gurba\\AppData\\Local\\Programs\\Python\\Python38\\lib\\site-packages\\ipykernel\\zmqshell.py\", line 528, in run_cell\n      return super().run_cell(*args, **kwargs)\n    File \"c:\\Users\\gurba\\AppData\\Local\\Programs\\Python\\Python38\\lib\\site-packages\\IPython\\core\\interactiveshell.py\", line 2881, in run_cell\n      result = self._run_cell(\n    File \"c:\\Users\\gurba\\AppData\\Local\\Programs\\Python\\Python38\\lib\\site-packages\\IPython\\core\\interactiveshell.py\", line 2936, in _run_cell\n      return runner(coro)\n    File \"c:\\Users\\gurba\\AppData\\Local\\Programs\\Python\\Python38\\lib\\site-packages\\IPython\\core\\async_helpers.py\", line 129, in _pseudo_sync_runner\n      coro.send(None)\n    File \"c:\\Users\\gurba\\AppData\\Local\\Programs\\Python\\Python38\\lib\\site-packages\\IPython\\core\\interactiveshell.py\", line 3135, in run_cell_async\n      has_raised = await self.run_ast_nodes(code_ast.body, cell_name,\n    File \"c:\\Users\\gurba\\AppData\\Local\\Programs\\Python\\Python38\\lib\\site-packages\\IPython\\core\\interactiveshell.py\", line 3338, in run_ast_nodes\n      if await self.run_code(code, result, async_=asy):\n    File \"c:\\Users\\gurba\\AppData\\Local\\Programs\\Python\\Python38\\lib\\site-packages\\IPython\\core\\interactiveshell.py\", line 3398, in run_code\n      exec(code_obj, self.user_global_ns, self.user_ns)\n    File \"C:\\Users\\gurba\\AppData\\Local\\Temp\\ipykernel_12728\\2186535113.py\", line 2, in <cell line: 2>\n      model.fit_generator(train_generator, steps_per_epoch=42, epochs=10, validation_data=test_generator, validation_steps=42)\n    File \"c:\\Users\\gurba\\AppData\\Local\\Programs\\Python\\Python38\\lib\\site-packages\\keras\\engine\\training.py\", line 2260, in fit_generator\n      return self.fit(\n    File \"c:\\Users\\gurba\\AppData\\Local\\Programs\\Python\\Python38\\lib\\site-packages\\keras\\utils\\traceback_utils.py\", line 64, in error_handler\n      return fn(*args, **kwargs)\n    File \"c:\\Users\\gurba\\AppData\\Local\\Programs\\Python\\Python38\\lib\\site-packages\\keras\\engine\\training.py\", line 1409, in fit\n      tmp_logs = self.train_function(iterator)\n    File \"c:\\Users\\gurba\\AppData\\Local\\Programs\\Python\\Python38\\lib\\site-packages\\keras\\engine\\training.py\", line 1051, in train_function\n      return step_function(self, iterator)\n    File \"c:\\Users\\gurba\\AppData\\Local\\Programs\\Python\\Python38\\lib\\site-packages\\keras\\engine\\training.py\", line 1040, in step_function\n      outputs = model.distribute_strategy.run(run_step, args=(data,))\n    File \"c:\\Users\\gurba\\AppData\\Local\\Programs\\Python\\Python38\\lib\\site-packages\\keras\\engine\\training.py\", line 1030, in run_step\n      outputs = model.train_step(data)\n    File \"c:\\Users\\gurba\\AppData\\Local\\Programs\\Python\\Python38\\lib\\site-packages\\keras\\engine\\training.py\", line 889, in train_step\n      y_pred = self(x, training=True)\n    File \"c:\\Users\\gurba\\AppData\\Local\\Programs\\Python\\Python38\\lib\\site-packages\\keras\\utils\\traceback_utils.py\", line 64, in error_handler\n      return fn(*args, **kwargs)\n    File \"c:\\Users\\gurba\\AppData\\Local\\Programs\\Python\\Python38\\lib\\site-packages\\keras\\engine\\training.py\", line 490, in __call__\n      return super().__call__(*args, **kwargs)\n    File \"c:\\Users\\gurba\\AppData\\Local\\Programs\\Python\\Python38\\lib\\site-packages\\keras\\utils\\traceback_utils.py\", line 64, in error_handler\n      return fn(*args, **kwargs)\n    File \"c:\\Users\\gurba\\AppData\\Local\\Programs\\Python\\Python38\\lib\\site-packages\\keras\\engine\\base_layer.py\", line 1014, in __call__\n      outputs = call_fn(inputs, *args, **kwargs)\n    File \"c:\\Users\\gurba\\AppData\\Local\\Programs\\Python\\Python38\\lib\\site-packages\\keras\\utils\\traceback_utils.py\", line 92, in error_handler\n      return fn(*args, **kwargs)\n    File \"c:\\Users\\gurba\\AppData\\Local\\Programs\\Python\\Python38\\lib\\site-packages\\keras\\engine\\sequential.py\", line 374, in call\n      return super(Sequential, self).call(inputs, training=training, mask=mask)\n    File \"c:\\Users\\gurba\\AppData\\Local\\Programs\\Python\\Python38\\lib\\site-packages\\keras\\engine\\functional.py\", line 458, in call\n      return self._run_internal_graph(\n    File \"c:\\Users\\gurba\\AppData\\Local\\Programs\\Python\\Python38\\lib\\site-packages\\keras\\engine\\functional.py\", line 596, in _run_internal_graph\n      outputs = node.layer(*args, **kwargs)\n    File \"c:\\Users\\gurba\\AppData\\Local\\Programs\\Python\\Python38\\lib\\site-packages\\keras\\utils\\traceback_utils.py\", line 64, in error_handler\n      return fn(*args, **kwargs)\n    File \"c:\\Users\\gurba\\AppData\\Local\\Programs\\Python\\Python38\\lib\\site-packages\\keras\\engine\\base_layer.py\", line 1014, in __call__\n      outputs = call_fn(inputs, *args, **kwargs)\n    File \"c:\\Users\\gurba\\AppData\\Local\\Programs\\Python\\Python38\\lib\\site-packages\\keras\\utils\\traceback_utils.py\", line 92, in error_handler\n      return fn(*args, **kwargs)\n    File \"c:\\Users\\gurba\\AppData\\Local\\Programs\\Python\\Python38\\lib\\site-packages\\keras\\layers\\reshaping\\flatten.py\", line 98, in call\n      return tf.reshape(inputs, flattened_shape)\nNode: 'sequential_2/flatten_2/Reshape'\nInput to reshape is a tensor with 52690176 values, but the requested shape requires a multiple of 28800\n\t [[{{node sequential_2/flatten_2/Reshape}}]] [Op:__inference_train_function_850]",
     "output_type": "error",
     "traceback": [
      "\u001b[1;31m---------------------------------------------------------------------------\u001b[0m",
      "\u001b[1;31mInvalidArgumentError\u001b[0m                      Traceback (most recent call last)",
      "\u001b[1;32mc:\\Users\\gurba\\OneDrive\\Documents\\AzeriAlphabetOCR\\main\\verydeeplearning.ipynb Cell 8\u001b[0m in \u001b[0;36m<cell line: 2>\u001b[1;34m()\u001b[0m\n\u001b[0;32m      <a href='vscode-notebook-cell:/c%3A/Users/gurba/OneDrive/Documents/AzeriAlphabetOCR/main/verydeeplearning.ipynb#X10sZmlsZQ%3D%3D?line=0'>1</a>\u001b[0m \u001b[39m# Train the model\u001b[39;00m\n\u001b[1;32m----> <a href='vscode-notebook-cell:/c%3A/Users/gurba/OneDrive/Documents/AzeriAlphabetOCR/main/verydeeplearning.ipynb#X10sZmlsZQ%3D%3D?line=1'>2</a>\u001b[0m model\u001b[39m.\u001b[39;49mfit_generator(train_generator, steps_per_epoch\u001b[39m=\u001b[39;49m\u001b[39m42\u001b[39;49m, epochs\u001b[39m=\u001b[39;49m\u001b[39m10\u001b[39;49m, validation_data\u001b[39m=\u001b[39;49mtest_generator, validation_steps\u001b[39m=\u001b[39;49m\u001b[39m42\u001b[39;49m)\n",
      "File \u001b[1;32mc:\\Users\\gurba\\AppData\\Local\\Programs\\Python\\Python38\\lib\\site-packages\\keras\\engine\\training.py:2260\u001b[0m, in \u001b[0;36mModel.fit_generator\u001b[1;34m(self, generator, steps_per_epoch, epochs, verbose, callbacks, validation_data, validation_steps, validation_freq, class_weight, max_queue_size, workers, use_multiprocessing, shuffle, initial_epoch)\u001b[0m\n\u001b[0;32m   2249\u001b[0m \u001b[39m\"\"\"Fits the model on data yielded batch-by-batch by a Python generator.\u001b[39;00m\n\u001b[0;32m   2250\u001b[0m \n\u001b[0;32m   2251\u001b[0m \u001b[39mDEPRECATED:\u001b[39;00m\n\u001b[0;32m   2252\u001b[0m \u001b[39m  `Model.fit` now supports generators, so there is no longer any need to use\u001b[39;00m\n\u001b[0;32m   2253\u001b[0m \u001b[39m  this endpoint.\u001b[39;00m\n\u001b[0;32m   2254\u001b[0m \u001b[39m\"\"\"\u001b[39;00m\n\u001b[0;32m   2255\u001b[0m warnings\u001b[39m.\u001b[39mwarn(\n\u001b[0;32m   2256\u001b[0m     \u001b[39m'\u001b[39m\u001b[39m`Model.fit_generator` is deprecated and \u001b[39m\u001b[39m'\u001b[39m\n\u001b[0;32m   2257\u001b[0m     \u001b[39m'\u001b[39m\u001b[39mwill be removed in a future version. \u001b[39m\u001b[39m'\u001b[39m\n\u001b[0;32m   2258\u001b[0m     \u001b[39m'\u001b[39m\u001b[39mPlease use `Model.fit`, which supports generators.\u001b[39m\u001b[39m'\u001b[39m,\n\u001b[0;32m   2259\u001b[0m     stacklevel\u001b[39m=\u001b[39m\u001b[39m2\u001b[39m)\n\u001b[1;32m-> 2260\u001b[0m \u001b[39mreturn\u001b[39;00m \u001b[39mself\u001b[39;49m\u001b[39m.\u001b[39;49mfit(\n\u001b[0;32m   2261\u001b[0m     generator,\n\u001b[0;32m   2262\u001b[0m     steps_per_epoch\u001b[39m=\u001b[39;49msteps_per_epoch,\n\u001b[0;32m   2263\u001b[0m     epochs\u001b[39m=\u001b[39;49mepochs,\n\u001b[0;32m   2264\u001b[0m     verbose\u001b[39m=\u001b[39;49mverbose,\n\u001b[0;32m   2265\u001b[0m     callbacks\u001b[39m=\u001b[39;49mcallbacks,\n\u001b[0;32m   2266\u001b[0m     validation_data\u001b[39m=\u001b[39;49mvalidation_data,\n\u001b[0;32m   2267\u001b[0m     validation_steps\u001b[39m=\u001b[39;49mvalidation_steps,\n\u001b[0;32m   2268\u001b[0m     validation_freq\u001b[39m=\u001b[39;49mvalidation_freq,\n\u001b[0;32m   2269\u001b[0m     class_weight\u001b[39m=\u001b[39;49mclass_weight,\n\u001b[0;32m   2270\u001b[0m     max_queue_size\u001b[39m=\u001b[39;49mmax_queue_size,\n\u001b[0;32m   2271\u001b[0m     workers\u001b[39m=\u001b[39;49mworkers,\n\u001b[0;32m   2272\u001b[0m     use_multiprocessing\u001b[39m=\u001b[39;49muse_multiprocessing,\n\u001b[0;32m   2273\u001b[0m     shuffle\u001b[39m=\u001b[39;49mshuffle,\n\u001b[0;32m   2274\u001b[0m     initial_epoch\u001b[39m=\u001b[39;49minitial_epoch)\n",
      "File \u001b[1;32mc:\\Users\\gurba\\AppData\\Local\\Programs\\Python\\Python38\\lib\\site-packages\\keras\\utils\\traceback_utils.py:67\u001b[0m, in \u001b[0;36mfilter_traceback.<locals>.error_handler\u001b[1;34m(*args, **kwargs)\u001b[0m\n\u001b[0;32m     65\u001b[0m \u001b[39mexcept\u001b[39;00m \u001b[39mException\u001b[39;00m \u001b[39mas\u001b[39;00m e:  \u001b[39m# pylint: disable=broad-except\u001b[39;00m\n\u001b[0;32m     66\u001b[0m   filtered_tb \u001b[39m=\u001b[39m _process_traceback_frames(e\u001b[39m.\u001b[39m__traceback__)\n\u001b[1;32m---> 67\u001b[0m   \u001b[39mraise\u001b[39;00m e\u001b[39m.\u001b[39mwith_traceback(filtered_tb) \u001b[39mfrom\u001b[39;00m \u001b[39mNone\u001b[39m\n\u001b[0;32m     68\u001b[0m \u001b[39mfinally\u001b[39;00m:\n\u001b[0;32m     69\u001b[0m   \u001b[39mdel\u001b[39;00m filtered_tb\n",
      "File \u001b[1;32mc:\\Users\\gurba\\AppData\\Local\\Programs\\Python\\Python38\\lib\\site-packages\\tensorflow\\python\\eager\\execute.py:54\u001b[0m, in \u001b[0;36mquick_execute\u001b[1;34m(op_name, num_outputs, inputs, attrs, ctx, name)\u001b[0m\n\u001b[0;32m     52\u001b[0m \u001b[39mtry\u001b[39;00m:\n\u001b[0;32m     53\u001b[0m   ctx\u001b[39m.\u001b[39mensure_initialized()\n\u001b[1;32m---> 54\u001b[0m   tensors \u001b[39m=\u001b[39m pywrap_tfe\u001b[39m.\u001b[39mTFE_Py_Execute(ctx\u001b[39m.\u001b[39m_handle, device_name, op_name,\n\u001b[0;32m     55\u001b[0m                                       inputs, attrs, num_outputs)\n\u001b[0;32m     56\u001b[0m \u001b[39mexcept\u001b[39;00m core\u001b[39m.\u001b[39m_NotOkStatusException \u001b[39mas\u001b[39;00m e:\n\u001b[0;32m     57\u001b[0m   \u001b[39mif\u001b[39;00m name \u001b[39mis\u001b[39;00m \u001b[39mnot\u001b[39;00m \u001b[39mNone\u001b[39;00m:\n",
      "\u001b[1;31mInvalidArgumentError\u001b[0m: Graph execution error:\n\nDetected at node 'sequential_2/flatten_2/Reshape' defined at (most recent call last):\n    File \"c:\\Users\\gurba\\AppData\\Local\\Programs\\Python\\Python38\\lib\\runpy.py\", line 194, in _run_module_as_main\n      return _run_code(code, main_globals, None,\n    File \"c:\\Users\\gurba\\AppData\\Local\\Programs\\Python\\Python38\\lib\\runpy.py\", line 87, in _run_code\n      exec(code, run_globals)\n    File \"c:\\Users\\gurba\\AppData\\Local\\Programs\\Python\\Python38\\lib\\site-packages\\ipykernel_launcher.py\", line 17, in <module>\n      app.launch_new_instance()\n    File \"c:\\Users\\gurba\\AppData\\Local\\Programs\\Python\\Python38\\lib\\site-packages\\traitlets\\config\\application.py\", line 976, in launch_instance\n      app.start()\n    File \"c:\\Users\\gurba\\AppData\\Local\\Programs\\Python\\Python38\\lib\\site-packages\\ipykernel\\kernelapp.py\", line 712, in start\n      self.io_loop.start()\n    File \"c:\\Users\\gurba\\AppData\\Local\\Programs\\Python\\Python38\\lib\\site-packages\\tornado\\platform\\asyncio.py\", line 215, in start\n      self.asyncio_loop.run_forever()\n    File \"c:\\Users\\gurba\\AppData\\Local\\Programs\\Python\\Python38\\lib\\asyncio\\base_events.py\", line 570, in run_forever\n      self._run_once()\n    File \"c:\\Users\\gurba\\AppData\\Local\\Programs\\Python\\Python38\\lib\\asyncio\\base_events.py\", line 1859, in _run_once\n      handle._run()\n    File \"c:\\Users\\gurba\\AppData\\Local\\Programs\\Python\\Python38\\lib\\asyncio\\events.py\", line 81, in _run\n      self._context.run(self._callback, *self._args)\n    File \"c:\\Users\\gurba\\AppData\\Local\\Programs\\Python\\Python38\\lib\\site-packages\\ipykernel\\kernelbase.py\", line 510, in dispatch_queue\n      await self.process_one()\n    File \"c:\\Users\\gurba\\AppData\\Local\\Programs\\Python\\Python38\\lib\\site-packages\\ipykernel\\kernelbase.py\", line 499, in process_one\n      await dispatch(*args)\n    File \"c:\\Users\\gurba\\AppData\\Local\\Programs\\Python\\Python38\\lib\\site-packages\\ipykernel\\kernelbase.py\", line 406, in dispatch_shell\n      await result\n    File \"c:\\Users\\gurba\\AppData\\Local\\Programs\\Python\\Python38\\lib\\site-packages\\ipykernel\\kernelbase.py\", line 730, in execute_request\n      reply_content = await reply_content\n    File \"c:\\Users\\gurba\\AppData\\Local\\Programs\\Python\\Python38\\lib\\site-packages\\ipykernel\\ipkernel.py\", line 383, in do_execute\n      res = shell.run_cell(\n    File \"c:\\Users\\gurba\\AppData\\Local\\Programs\\Python\\Python38\\lib\\site-packages\\ipykernel\\zmqshell.py\", line 528, in run_cell\n      return super().run_cell(*args, **kwargs)\n    File \"c:\\Users\\gurba\\AppData\\Local\\Programs\\Python\\Python38\\lib\\site-packages\\IPython\\core\\interactiveshell.py\", line 2881, in run_cell\n      result = self._run_cell(\n    File \"c:\\Users\\gurba\\AppData\\Local\\Programs\\Python\\Python38\\lib\\site-packages\\IPython\\core\\interactiveshell.py\", line 2936, in _run_cell\n      return runner(coro)\n    File \"c:\\Users\\gurba\\AppData\\Local\\Programs\\Python\\Python38\\lib\\site-packages\\IPython\\core\\async_helpers.py\", line 129, in _pseudo_sync_runner\n      coro.send(None)\n    File \"c:\\Users\\gurba\\AppData\\Local\\Programs\\Python\\Python38\\lib\\site-packages\\IPython\\core\\interactiveshell.py\", line 3135, in run_cell_async\n      has_raised = await self.run_ast_nodes(code_ast.body, cell_name,\n    File \"c:\\Users\\gurba\\AppData\\Local\\Programs\\Python\\Python38\\lib\\site-packages\\IPython\\core\\interactiveshell.py\", line 3338, in run_ast_nodes\n      if await self.run_code(code, result, async_=asy):\n    File \"c:\\Users\\gurba\\AppData\\Local\\Programs\\Python\\Python38\\lib\\site-packages\\IPython\\core\\interactiveshell.py\", line 3398, in run_code\n      exec(code_obj, self.user_global_ns, self.user_ns)\n    File \"C:\\Users\\gurba\\AppData\\Local\\Temp\\ipykernel_12728\\2186535113.py\", line 2, in <cell line: 2>\n      model.fit_generator(train_generator, steps_per_epoch=42, epochs=10, validation_data=test_generator, validation_steps=42)\n    File \"c:\\Users\\gurba\\AppData\\Local\\Programs\\Python\\Python38\\lib\\site-packages\\keras\\engine\\training.py\", line 2260, in fit_generator\n      return self.fit(\n    File \"c:\\Users\\gurba\\AppData\\Local\\Programs\\Python\\Python38\\lib\\site-packages\\keras\\utils\\traceback_utils.py\", line 64, in error_handler\n      return fn(*args, **kwargs)\n    File \"c:\\Users\\gurba\\AppData\\Local\\Programs\\Python\\Python38\\lib\\site-packages\\keras\\engine\\training.py\", line 1409, in fit\n      tmp_logs = self.train_function(iterator)\n    File \"c:\\Users\\gurba\\AppData\\Local\\Programs\\Python\\Python38\\lib\\site-packages\\keras\\engine\\training.py\", line 1051, in train_function\n      return step_function(self, iterator)\n    File \"c:\\Users\\gurba\\AppData\\Local\\Programs\\Python\\Python38\\lib\\site-packages\\keras\\engine\\training.py\", line 1040, in step_function\n      outputs = model.distribute_strategy.run(run_step, args=(data,))\n    File \"c:\\Users\\gurba\\AppData\\Local\\Programs\\Python\\Python38\\lib\\site-packages\\keras\\engine\\training.py\", line 1030, in run_step\n      outputs = model.train_step(data)\n    File \"c:\\Users\\gurba\\AppData\\Local\\Programs\\Python\\Python38\\lib\\site-packages\\keras\\engine\\training.py\", line 889, in train_step\n      y_pred = self(x, training=True)\n    File \"c:\\Users\\gurba\\AppData\\Local\\Programs\\Python\\Python38\\lib\\site-packages\\keras\\utils\\traceback_utils.py\", line 64, in error_handler\n      return fn(*args, **kwargs)\n    File \"c:\\Users\\gurba\\AppData\\Local\\Programs\\Python\\Python38\\lib\\site-packages\\keras\\engine\\training.py\", line 490, in __call__\n      return super().__call__(*args, **kwargs)\n    File \"c:\\Users\\gurba\\AppData\\Local\\Programs\\Python\\Python38\\lib\\site-packages\\keras\\utils\\traceback_utils.py\", line 64, in error_handler\n      return fn(*args, **kwargs)\n    File \"c:\\Users\\gurba\\AppData\\Local\\Programs\\Python\\Python38\\lib\\site-packages\\keras\\engine\\base_layer.py\", line 1014, in __call__\n      outputs = call_fn(inputs, *args, **kwargs)\n    File \"c:\\Users\\gurba\\AppData\\Local\\Programs\\Python\\Python38\\lib\\site-packages\\keras\\utils\\traceback_utils.py\", line 92, in error_handler\n      return fn(*args, **kwargs)\n    File \"c:\\Users\\gurba\\AppData\\Local\\Programs\\Python\\Python38\\lib\\site-packages\\keras\\engine\\sequential.py\", line 374, in call\n      return super(Sequential, self).call(inputs, training=training, mask=mask)\n    File \"c:\\Users\\gurba\\AppData\\Local\\Programs\\Python\\Python38\\lib\\site-packages\\keras\\engine\\functional.py\", line 458, in call\n      return self._run_internal_graph(\n    File \"c:\\Users\\gurba\\AppData\\Local\\Programs\\Python\\Python38\\lib\\site-packages\\keras\\engine\\functional.py\", line 596, in _run_internal_graph\n      outputs = node.layer(*args, **kwargs)\n    File \"c:\\Users\\gurba\\AppData\\Local\\Programs\\Python\\Python38\\lib\\site-packages\\keras\\utils\\traceback_utils.py\", line 64, in error_handler\n      return fn(*args, **kwargs)\n    File \"c:\\Users\\gurba\\AppData\\Local\\Programs\\Python\\Python38\\lib\\site-packages\\keras\\engine\\base_layer.py\", line 1014, in __call__\n      outputs = call_fn(inputs, *args, **kwargs)\n    File \"c:\\Users\\gurba\\AppData\\Local\\Programs\\Python\\Python38\\lib\\site-packages\\keras\\utils\\traceback_utils.py\", line 92, in error_handler\n      return fn(*args, **kwargs)\n    File \"c:\\Users\\gurba\\AppData\\Local\\Programs\\Python\\Python38\\lib\\site-packages\\keras\\layers\\reshaping\\flatten.py\", line 98, in call\n      return tf.reshape(inputs, flattened_shape)\nNode: 'sequential_2/flatten_2/Reshape'\nInput to reshape is a tensor with 52690176 values, but the requested shape requires a multiple of 28800\n\t [[{{node sequential_2/flatten_2/Reshape}}]] [Op:__inference_train_function_850]"
     ]
    }
   ],
   "source": [
    "# Train the model\n",
    "model.fit_generator(train_generator, steps_per_epoch=42, epochs=10, validation_data=test_generator, validation_steps=42)"
   ]
  }
 ],
 "metadata": {
  "kernelspec": {
   "display_name": "Python 3.8.6 64-bit",
   "language": "python",
   "name": "python3"
  },
  "language_info": {
   "codemirror_mode": {
    "name": "ipython",
    "version": 3
   },
   "file_extension": ".py",
   "mimetype": "text/x-python",
   "name": "python",
   "nbconvert_exporter": "python",
   "pygments_lexer": "ipython3",
   "version": "3.8.6"
  },
  "vscode": {
   "interpreter": {
    "hash": "4958a4d708202592358e63aad7fe75dd7d369992d56d971d9aa6cd31d1b68dd5"
   }
  }
 },
 "nbformat": 4,
 "nbformat_minor": 5
}
